<?xml version="1.0"?>
<robot xmlns:xacro="http://www.ros.org/wiki/xacro" name="example">
  <xacro:arg name="gpu" default="false"/>
  <xacro:property name="gpu" value="$(arg gpu)" />
  <xacro:arg name="organize_cloud" default="false"/>
  <xacro:property name="organize_cloud" value="$(arg organize_cloud)" />

  <!-- Base Footprint -->
  <link name="base_footprint" />

  <!-- Base Link -->
  <joint name="footprint" type="fixed" >
    <parent link="base_footprint"/>
    <child link="base_link" />
    <origin xyz="0 0 0.05" rpy="0 0 0" />
  </joint>

  <link name="base_link" >
    <visual>
      <geometry>
        <box size="0.5 0.75 0.1" />
      </geometry>
    </visual>
    <collision>
      <geometry>
        <box size="0.5 0.75 0.1" />
      </geometry>
    </collision>
    <inertial>
      <origin xyz="0 0 0"/>
      <mass value="10"/>
      <inertia ixx="3.0" ixy="0.0" ixz="0.0"
               iyy="3.0" iyz="0.0"
               izz="3.0" />
    </inertial>
  </link>

  <!-- right front wheel link -->
  <joint name="right_front_wheel_joint" type="continuous">
    <axis xyz="0 0 1"/>
    <parent link="base_link"/>
    <child link="right_front_wheel"/>
    <origin rpy="0 1.57075 0" xyz="0.3 0.3 0"/>
    <limit effort="100" velocity="100"/>
    <joint_properties damping="0.0" friction="0.0"/>
  </joint>

  <link name="right_front_wheel">
    <visual>
      <geometry>
        <cylinder length=".08" radius="0.15"/>
      </geometry>
    </visual>
    <collision>
      <geometry>
        <cylinder length=".08" radius="0.15"/>
      </geometry>
    </collision>
    <inertial>
      <origin rpy="0 1.57075 0" xyz="0.3 0.3 0"/>
      <mass value="10"/>
      <inertia ixx="3.0" ixy="0.0" ixz="0.0"
               iyy="3.0" iyz="0.0"
               izz="3.0" />
    </inertial>
  </link>

  <!-- left front wheel link -->
  <joint name="left_front_wheel_joint" type="continuous">
    <axis xyz="0 0 1"/>
    <parent link="base_link"/>
    <child link="left_front_wheel"/>
    <origin rpy="0 1.57075 0" xyz="-0.3 0.3 0"/>
    <limit effort="100" velocity="100"/>
    <joint_properties damping="0.0" friction="0.0"/>
  </joint>

  <link name="left_front_wheel">
    <visual>
      <geometry>
        <cylinder length=".08" radius="0.15"/>
      </geometry>
    </visual>
    <collision>
      <geometry>
        <cylinder length=".08" radius="0.15"/>
      </geometry>
    </collision>
    <inertial>
      <origin rpy="0 1.57075 0" xyz="-0.3 0.3 0"/>
      <mass value="10"/>
      <inertia ixx="3.0" ixy="0.0" ixz="0.0"
               iyy="3.0" iyz="0.0"
               izz="3.0" />
    </inertial>
  </link>

  <!-- right back wheel link -->
  <joint name="right_back_wheel_joint" type="continuous">
    <axis xyz="0 0 1"/>
    <parent link="base_link"/>
    <child link="right_back_wheel"/>
    <origin rpy="0 1.57075 0" xyz="0.3 -0.3 0"/>
    <limit effort="100" velocity="100"/>
    <joint_properties damping="0.0" friction="0.0"/>
  </joint>

  <link name="right_back_wheel">
    <visual>
      <geometry>
        <cylinder length=".08" radius="0.15"/>
      </geometry>
    </visual>
    <collision>
      <geometry>
        <cylinder length=".08" radius="0.15"/>
      </geometry>
    </collision>
    <inertial>
      <origin rpy="0 1.57075 0" xyz="0.3 0.3 0"/>
      <mass value="10"/>
      <inertia ixx="3.0" ixy="0.0" ixz="0.0"
               iyy="3.0" iyz="0.0"
               izz="3.0" />
    </inertial>
  </link>

  <!-- left back wheel link -->
  <joint name="left_back_wheel_joint" type="continuous">
    <axis xyz="0 0 1"/>
    <parent link="base_link"/>
    <child link="left_back_wheel"/>
    <origin rpy="0 1.57075 0" xyz="-0.3 -0.3 0"/>
    <limit effort="100" velocity="100"/>
    <joint_properties damping="0.0" friction="0.0"/>
  </joint>

  <link name="left_back_wheel">
    <visual>
      <geometry>
        <cylinder length=".08" radius="0.15"/>
      </geometry>
    </visual>
    <collision>
      <geometry>
        <cylinder length=".08" radius="0.15"/>
      </geometry>
    </collision>
    <inertial>
      <origin rpy="0 1.57075 0" xyz="-0.3 0.3 0"/>
      <mass value="10"/>
      <inertia ixx="3.0" ixy="0.0" ixz="0.0"
               iyy="3.0" iyz="0.0"
               izz="3.0" />
    </inertial>
  </link>




  <xacro:include filename="$(find velodyne_description)/urdf/VLP-16.urdf.xacro"/>
  <xacro:VLP-16 parent="base_link" name="velodyne" topic="/velodyne_points" organize_cloud="${organize_cloud}" hz="10" samples="440" gpu="${gpu}">
    <origin xyz="0 0 1" rpy="0 0 0" />
  </xacro:VLP-16>

  <!-- <xacro:include filename="$(find velodyne_description)/urdf/HDL-32E.urdf.xacro"/>
  <xacro:HDL-32E parent="base_link" name="velodyne2" topic="/velodyne_points2" organize_cloud="${organize_cloud}" hz="10" samples="220" gpu="${gpu}">
    <origin xyz="0 0 0.6" rpy="0 0 0" />
  </xacro:HDL-32E> -->

  <!-- Imu link and plugin -->
  <gazebo>
    <plugin name="imu_plugin" filename="libgazebo_ros_imu.so">
      <alwaysOn>true</alwaysOn>
      <bodyName>base_footprint</bodyName>
      <topicName>imu</topicName>
      <serviceName>imu_service</serviceName>
      <gaussianNoise>0.0</gaussianNoise>
      <updateRate>20.0</updateRate>
    </plugin>
  </gazebo>

  <!-- <gazebo reference="base_link">
    <gravity>true</gravity>
    <sensor name="imu_sensor" type="imu">
      <always_on>true</always_on>
      <update_rate>100</update_rate>
      <visualize>true</visualize>
      <topic>__default_topic__</topic>
      <plugin filename="libgazebo_ros_imu_sensor.so" name="imu_plugin">
        <topicName>imu</topicName>
        <bodyName>base_link</bodyName>
        <updateRateHZ>100.0</updateRateHZ>
        <gaussianNoise>0.0</gaussianNoise>
        <xyzOffset>0 0 0</xyzOffset>
        <rpyOffset>0 0 0</rpyOffset>
        <frameName>base_link</frameName>
        <initialOrientationAsReference>false</initialOrientationAsReference>
      </plugin>
      <pose>0 0 0 0 0 0</pose>
    </sensor>
  </gazebo> -->





</robot>
